<?xml version="1.0" encoding="utf-8"?>
<!-- This URDF was automatically created by SolidWorks to URDF Exporter! Originally created by Stephen Brawner (brawner@gmail.com) 
     Commit Version: 1.6.0-1-g15f4949  Build Version: 1.6.7594.29634
     For more information, please see http://wiki.ros.org/sw_urdf_exporter -->
<robot
  name="mapping_robot_1">
  <link
    name="base_link">
    <inertial>
      <origin xyz="0 0 0.03" rpy="0 0 0" />
      <mass value="0.36019" />
      <inertia
        ixx="0.0010507"
        ixy="7.6565E-12"
        ixz="4.6942E-11"
        iyy="0.0018673"
        iyz="0.3788E-10"
        izz="0.00107787" />
    </inertial>
    <visual>
      <origin xyz="0 0 0" rpy="0 0 0" />
      <geometry>
        <mesh filename="package://mapping_robot_1/meshes/base_link.STL" />
      </geometry>
      <material
        name="">
        <color rgba="0.79216 0.81961 0.93333 1" />
      </material>
    </visual>
    <collision>
      <origin xyz="0 0 0" rpy="0 0 0" />
      <geometry>
        <mesh filename="package://mapping_robot_1/meshes/base_link.STL" />
      </geometry>
    </collision>
  </link>

  <gazebo reference="base_link">
    <material>Gazebo/DarkGrey</material>
  </gazebo>

  <joint name="caster_joint" type="fixed">
    <origin xyz="0 0.08 -0.02" rpy="0 0 0"/>
    <parent link="base_link"/>
    <child link="caster_front"/>
  </joint>

  <gazebo reference="caster_front">
            <slip1>100000.0</slip1>
            <slip2>100000.0</slip2>
  </gazebo>

 <link name="caster_front">
    <collision name="caster_front_collision">
      <origin rpy="0  0  0" xyz="0 0 0"/>
      <geometry>
        <sphere radius="0.018"/>
      </geometry>
      <surface>
        <friction>
          <ode>
            <slip1>100000.0</slip1>
            <slip2>100000.0</slip2>
          </ode>
        </friction>
      </surface>
    </collision>
    
    <visual name="castor_front_visual">
      <origin rpy="0  0  0" xyz="0 0 0"/>
      <geometry>
        <sphere radius="0.018"/>
      </geometry>
      <material
        name="">
        <color rgba="0.79216 0.81961 0.93333 1" />
      </material>
    </visual>
  </link>

 <gazebo reference="caster_front">
    <material>Gazebo/BlueGlow</material>
  </gazebo>

  <joint name="caster_joint1" type="fixed">
    <origin xyz="0 -0.08 -0.02" rpy="0 0 0"/>
    <parent link="base_link"/>
    <child link="caster_front1"/>
  </joint>

    <gazebo reference="caster_front1">
            <slip1>100000.0</slip1>
            <slip2>100000.0</slip2>
  </gazebo>
 <link name="caster_front1">
    <collision name="caster_front_collision1">
      <origin rpy="0  0  0" xyz="0 0 0"/>
      <geometry>
        <sphere radius="0.015"/>
      </geometry>
      <surface>
        <friction>
          <ode>
            <slip1>100000.0</slip1>
            <slip2>100000.0</slip2>
          </ode>
        </friction>
      </surface>
    </collision>
    
    <visual name="castor_front_visual1">
      <origin rpy="0  0  0" xyz="0 0 0"/>
      <geometry>
        <sphere radius="0.015"/>
      </geometry>
      <material
        name="1">
        <color rgba="0.9216 0.81961 0.93333 1" />
      </material>
    </visual> 
    </link>

  <gazebo reference="caster_front1">
    <material>Gazebo/BlueGlow</material>
  </gazebo>

  <joint name="stereo_joint" type="fixed">
    <origin xyz="0.0 0.065 0.21" rpy="0 0 1.57"/>
    <parent link="base_link"/>
    <child link="stereo_link"/>
  </joint>

  <link name="stereo_link">
    <collision>
      <origin xyz="0.0 0.0 0.0" rpy="0 0 0"/>
      <geometry>
        <box size="0.007 0.035 0.01"/>
      </geometry>
    </collision>
    <visual name="stereo_front_visual">
      <origin rpy="0  0  0" xyz="0  0  0"/>
      <geometry>
        <box size="0.007 0.035 0.01"/>
      </geometry>
    </visual> 
  </link>
  
  <link
    name="Left_link">
    <inertial>
      <origin xyz="0.07 0.0 -0.009" rpy="0 0 0" />
      <mass value="0.0047382" />
      <inertia
        ixx="2.7571E-06"
        ixy="-6.1198E-12"
        ixz="1.7319E-14"
        iyy="1.3915E-06"
        iyz="-3.1568E-13"
        izz="1.3915E-06" />
    </inertial>
    <visual>
      <origin xyz="-0.135 0 0" rpy="0 0 0" />
      <geometry>
        <mesh filename="package://mapping_robot_1/meshes/Left_link.STL" />
      </geometry>
      <material
        name="">
        <color rgba="0.79216 0.81961 0.93333 1" />
      </material>
    </visual>
    <collision>
      <origin xyz="-0.135 0 0" rpy="0 0 0" />
      <geometry>
        <mesh filename="package://mapping_robot_1/meshes/Left_link.STL" />
      </geometry>
      <surface>
      <friction>
          <ode>
            <mu>1000</mu>
            <mu2>1000</mu2>
          </ode>
        </friction>
      </surface>
    </collision>
  </link>
  <joint name="left_wheel" type="continuous">
    <origin xyz="0.07 0.0 -0.009" rpy="0 0 0" />
    <parent link="base_link" />
    <child link="Left_link" />
    <axis xyz="-1 0 0" />
    <limit effort="20" velocity="10" /> 
    <joint_properties damping="10.0" friction="10000.0" />
  </joint>

  <gazebo reference="Left_link">
            <mu>1000</mu>
            <mu2>1000</mu2>
  </gazebo>
  <transmission name="left_wheel_trans">
    <type>transmission_interface/SimpleTransmission</type>
    <actuator name="left_wheel_motor">
      <hardwareInterface>VelocityJointInterface</hardwareInterface>
      <mechanicalReduction>4</mechanicalReduction>
    </actuator>
    <joint name="left_wheel">
      <hardwareInterface>VelocityJointInterface</hardwareInterface>
    </joint>
  </transmission>

  <gazebo reference="Left_link">
    <material>Gazebo/BlueGlow</material>
  </gazebo>

  <link name="Right_Link">
    <inertial>
      <origin xyz="-0.07 0.0 -0.009" rpy="0 0 0" />
      <mass value="0.0047382" />
      <inertia
        ixx="2.7571E-06"
        ixy="-6.1198E-12"
        ixz="1.7319E-14"
        iyy="1.3915E-06"
        iyz="-3.1568E-13"
        izz="1.3915E-06" />
    </inertial>
    <visual>
      <origin xyz="0.135 0 0" rpy="0 0 0" />
      <geometry>
        <mesh filename="package://mapping_robot_1/meshes/Right_Link.STL" />
      </geometry>
      <material
        name="">
        <color rgba="0.79216 0.81961 0.93333 1" />
      </material>
    </visual>
    <collision>
      <origin xyz="0.135 0.0 0.0" rpy="0 0 0" />
      <geometry>
        <mesh filename="package://mapping_robot_1/meshes/Right_Link.STL" />
      </geometry>
      <surface>
      <friction>
          <ode>
            <mu>100</mu>
            <mu2>100</mu2>
          </ode>
        </friction>
      </surface>
    </collision>
  </link>
  <joint name="Right_wheel" type="continuous">
    <origin xyz="-0.07 0.0 -0.009" rpy="0 0 0" />
    <parent link="base_link" />
    <child link="Right_Link" />
    <axis xyz="-1 0 0" />
    <limit effort="20" velocity="10" /> 
    <joint_properties damping="10.0" friction="10000.0" />
  </joint>

  
  <gazebo reference="Right_Link">
            <mu>1000</mu>
            <mu2>1000</mu2>
  </gazebo>
  <transmission name="right_wheel_trans">
     <type>transmission_interface/SimpleTransmission</type>
     <actuator name="right_wheel_motor">
       <hardwareInterface>VelocityJointInterface</hardwareInterface>
       <mechanicalReduction>4</mechanicalReduction>
     </actuator>
     <joint name="Right_wheel">
       <hardwareInterface>VelocityJointInterface</hardwareInterface>
     </joint>
  </transmission>

  <gazebo reference="Right_Link">
    <material>Gazebo/BlueGlow</material>
  </gazebo>

  <gazebo>
    <plugin filename="libgazebo_ros_diff_drive.so" name="differential_drive_controller">
      <alwaysOn>true</alwaysOn>
      <updateRate>20</updateRate>
      <leftJoint>left_wheel</leftJoint>
      <rightJoint>Right_wheel</rightJoint>
      <wheelSeparation>0.2</wheelSeparation>
      <wheelDiameter>0.1</wheelDiameter>
      <torque>10</torque>
      <commandTopic>cmd_vel</commandTopic>
      <odometryTopic>odom</odometryTopic>
      <odometryFrame>odom</odometryFrame>
      <robotBaseFrame>base_link</robotBaseFrame>
    </plugin>
  </gazebo>
<!-- First camera joint -->
  <joint name="camera_joint" type="fixed">
    <origin xyz="0.0165 0.065 0.21" rpy="0 0 1.57"/>
    <parent link="base_link"/>
    <child link="camera_link"/>
  </joint>

  <link name="camera_link">
    <collision>
      <origin xyz="0.001325 0.002915 0.003445" rpy="0 0 0"/>
      <geometry>
        <box size="0.003975 0.00795 0.007155"/>
      </geometry>
    </collision>
  </link>

  <joint name="camera_rgb_joint" type="fixed">
    <origin xyz="0.000795 0.002915 0.002385" rpy="0 0 0"/>
    <parent link="camera_link"/>
    <child link="camera_rgb_frame"/>
  </joint>
  <link name="camera_rgb_frame"/>

  <joint name="camera_rgb_optical_joint" type="fixed">
    <origin xyz="0 0 0" rpy="-1.57 0 -1.57"/>
    <parent link="camera_rgb_frame"/>
    <child link="camera_rgb_optical_frame"/>
  </joint>
  <link name="camera_rgb_optical_frame"/>

    <gazebo reference="camera_rgb_frame">
    <sensor type="camera" name="Pi Camera">
      <always_on>true</always_on>
      <visualize>true</visualize>
      <camera>
          <horizontal_fov>1.085595</horizontal_fov>
          <image>
              <width>640</width>
              <height>480</height>
              <format>R8G8B8</format>
          </image>
          <clip>
              <near>0.03</near>
              <far>100</far>
          </clip>
      </camera>
      <plugin name="camera_controller" filename="libgazebo_ros_camera.so">
        <alwaysOn>true</alwaysOn>
        <updateRate>30.0</updateRate>
        <cameraName>camera</cameraName>
        <frameName>camera_rgb_optical_frame</frameName>
        <imageTopicName>rgb/image_raw</imageTopicName>
        <cameraInfoTopicName>rgb/camera_info</cameraInfoTopicName>
        <hackBaseline>0.07</hackBaseline>
        <distortionK1>0.0</distortionK1>
        <distortionK2>0.0</distortionK2>
        <distortionK3>0.0</distortionK3>
        <distortionT1>0.0</distortionT1>
        <distortionT2>0.0</distortionT2>
      </plugin>
    </sensor>
  </gazebo>
<!-- The second Camera joint -->
  <joint name="camera_joint1" type="fixed">
    <origin xyz="-0.0135 0.065 0.21" rpy="0 0 1.57"/>
    <parent link="base_link"/>
    <child link="camera_link1"/>
  </joint>

  <link name="camera_link1">
    <collision>
      <origin xyz="0.001325 0.002915 0.003445" rpy="0 0 0"/>
      <geometry>
        <box size="0.003975 0.00795 0.007155"/>
      </geometry>
    </collision>
  </link>

  <joint name="camera_rgb_joint1" type="fixed">
    <origin xyz="0.000795 0.002915 0.002385" rpy="0 0 0"/>
    <parent link="camera_link1"/>
    <child link="camera_rgb_frame1"/>
  </joint>
  <link name="camera_rgb_frame1"/>

  <joint name="camera_rgb_optical_joint1" type="fixed">
    <origin xyz="0 0 0" rpy="-1.57 0 -1.57"/>
    <parent link="camera_rgb_frame1"/>
    <child link="camera_rgb_optical_frame1"/>
  </joint>
  <link name="camera_rgb_optical_frame1"/>

    <gazebo reference="camera_rgb_frame1">
    <sensor type="camera" name="Pi Camera">
      <always_on>true</always_on>
      <visualize>true</visualize>
      <camera>
          <horizontal_fov>1.085595</horizontal_fov>
          <image>
              <width>640</width>
              <height>480</height>
              <format>R8G8B8</format>
          </image>
          <clip>
              <near>0.03</near>
              <far>100</far>
          </clip>
      </camera>
      <plugin name="camera_controller" filename="libgazebo_ros_camera.so">
        <alwaysOn>true</alwaysOn>
        <updateRate>30.0</updateRate>
        <cameraName>camera1</cameraName>
        <frameName>camera_rgb_optical_frame1</frameName>
        <imageTopicName>rgb/image_raw1</imageTopicName>
        <cameraInfoTopicName>rgb/camera_info1</cameraInfoTopicName>
        <hackBaseline>0.07</hackBaseline>
        <distortionK1>0.0</distortionK1>
        <distortionK2>0.0</distortionK2>
        <distortionK3>0.0</distortionK3>
        <distortionT1>0.0</distortionT1>
        <distortionT2>0.0</distortionT2>
      </plugin>
    </sensor>
  </gazebo>
</robot>